#VRML_SIM R2025a utf8

EXTERNPROTO "https://raw.githubusercontent.com/cyberbotics/webots/R2025a/projects/objects/backgrounds/protos/TexturedBackground.proto"
EXTERNPROTO "https://raw.githubusercontent.com/cyberbotics/webots/R2025a/projects/objects/backgrounds/protos/TexturedBackgroundLight.proto"
EXTERNPROTO "https://raw.githubusercontent.com/cyberbotics/webots/R2025a/projects/objects/floors/protos/CircleArena.proto"

WorldInfo {
  basicTimeStep 12
}
Viewpoint {
  orientation -0.46633107620685343 -0.4089574256631652 0.7844036915764194 4.346712372529701
  position 1.0838009964348778 9.217150561888328 28.129126036681463
}
TexturedBackground {
}
TexturedBackgroundLight {
}
CircleArena {
  radius 10
}
CircleArena {
  translation 20 0 0
  name "circle arena(1)"
  radius 10
}
Robot {
  translation 0.21 -0.46 3.11
  children [
    HingeJoint {
      jointParameters HingeJointParameters {
        axis 0 0 1
        anchor -0.33 -0.0999998 -2.13
      }
      device [
        RotationalMotor {
          name "aspa_motor_ct18"
        }
      ]
      endPoint Solid {
        translation -0.33 0.0999998 -2.13
        rotation 0 0 1 0.2617989999999993
        children [
          DEF ASPA_SERVO Shape {
            appearance PBRAppearance {
              roughness 1
              metalness 0
            }
            geometry Box {
              size 0.75 3.5 0.3
            }
          }
        ]
        name "solid(1)"
      }
    }
    Solid {
      translation -0.0043988 0.109912 -1.38
      rotation 0 0 1 0.04
      children [
        DEF SERVO Shape {
          appearance PBRAppearance {
            baseColor 0 0 1
            transparency 0.05
            roughness 1
            metalness 0
          }
          geometry Box {
            size 2.4 1.8 1.2
          }
        }
      ]
    }
  ]
  name "servo_ct18"
  controller "mover_servo_ct18"
}
Robot {
  translation 0.2 -0.46 7.1
  children [
    HingeJoint {
      jointParameters HingeJointParameters {
        axis 0 0 1
        anchor -0.33 -0.0999998 -2.13
      }
      device [
        RotationalMotor {
          name "aspa_motor_ct15"
        }
      ]
      endPoint Solid {
        translation -0.33 0.0999998 -2.13
        rotation 0 0 1 0.2617989999999993
        children [
          DEF ASPA_SERVO Shape {
            appearance PBRAppearance {
              roughness 1
              metalness 0
            }
            geometry Box {
              size 0.75 3.5 0.3
            }
          }
        ]
        name "solid(1)"
      }
    }
    Solid {
      translation -0.0043988 0.109912 -1.38
      rotation 0 0 1 0.04
      children [
        DEF SERVO Shape {
          appearance PBRAppearance {
            baseColor 0 0 1
            transparency 0.05
            roughness 1
            metalness 0
          }
          geometry Box {
            size 2.4 1.8 1.2
          }
        }
      ]
    }
  ]
  name "servo_ct15"
  controller "mover_servo_ct15"
}
Robot {
  translation 0.19 -0.46 11.16
  children [
    HingeJoint {
      jointParameters HingeJointParameters {
        axis 0 0 1
        anchor -0.33 -0.0999998 -2.13
      }
      device [
        RotationalMotor {
          name "aspa_motor_ct12"
        }
      ]
      endPoint Solid {
        translation -0.33 0.0999998 -2.13
        rotation 0 0 1 0.2617989999999993
        children [
          DEF ASPA_SERVO Shape {
            appearance PBRAppearance {
              roughness 1
              metalness 0
            }
            geometry Box {
              size 0.75 3.5 0.3
            }
          }
        ]
        name "solid(1)"
      }
    }
    Solid {
      translation -0.0043988 0.109912 -1.38
      rotation 0 0 1 0.04
      children [
        DEF SERVO Shape {
          appearance PBRAppearance {
            baseColor 0 0 1
            transparency 0.05
            roughness 1
            metalness 0
          }
          geometry Box {
            size 2.4 1.8 1.2
          }
        }
      ]
    }
  ]
  name "servo_ct12"
  controller "mover_servo_ct12"
}
Robot {
  translation -0.11251841825786181 -0.39190549500475075 -0.005162649938375896
  rotation 0.0017485402009863144 0.00015810603679987126 0.9999984588036358 0.04076242876803916
  children [
    Group {
      children [
        Solid {
          translation 0 0 10.14
          children [
            DEF C12 Shape {
              appearance PBRAppearance {
                metalness 0
              }
              geometry Mesh {
                url [
                  "../meshes/contenedores_12.obj"
                ]
              }
            }
          ]
          name "C12"
          boundingObject USE C12
          physics DEF M3D Physics {
            density -1
            mass 1
            damping Damping {
            }
          }
        }
        Solid {
          translation 0 0 8.1
          rotation 0 0 1 1.8
          children [
            DEF ROTOR Shape {
              appearance PBRAppearance {
              }
              geometry Mesh {
                url [
                  "../meshes/rotor.obj"
                ]
              }
            }
          ]
          name "R1"
          boundingObject USE ROTOR
          physics USE M3D
        }
        Solid {
          translation 0 0 6.03
          children [
            DEF C15 Shape {
              appearance PBRAppearance {
                metalness 0
              }
              geometry Mesh {
                url [
                  "../meshes/contenedores_15.obj"
                ]
              }
            }
          ]
          name "C15"
          boundingObject USE C15
          physics USE M3D
        }
        Solid {
          translation 0 0 3.98
          rotation 0 0 1 1.8
          children [
            DEF ROTOR Shape {
              appearance PBRAppearance {
              }
              geometry Mesh {
                url [
                  "../meshes/rotor.obj"
                ]
              }
            }
          ]
          name "R2"
          boundingObject USE ROTOR
          physics USE M3D
        }
        Solid {
          translation 0.01603261661669573 0.07648490477701853 1.9985128709514854
          rotation 0.01899286689548021 -0.009673869771031584 0.9997728178195002 0.0008207718687865466
          children [
            DEF C18 Shape {
              appearance PBRAppearance {
                metalness 0
              }
              geometry Mesh {
                url [
                  "../meshes/contenedores_18.obj"
                ]
              }
            }
          ]
          name "C18"
          boundingObject USE C18
          physics USE M3D
        }
        Solid {
          translation 0 0 -0.07
          rotation 0 0 1 1.8
          children [
            DEF ROTOR Shape {
              appearance PBRAppearance {
              }
              geometry Mesh {
                url [
                  "../meshes/rotor.obj"
                ]
              }
            }
          ]
          name "R3"
          boundingObject USE ROTOR
          physics USE M3D
        }
      ]
    }
  ]
  name "alfredo"
  physics USE M3D
}
